//read the documentation of promises from mdn docs 
// https://developer.mozilla.org/en-US/docs/Web/JavaScript/Reference/Global_Objects/Promise

const promiseOne = new Promise(function(resolve, reject){
    //Do an async task
    // DB calls, cryptography, network
    setTimeout(function(){
        console.log('Async task is compelete');
        resolve()
    }, 1000)
})

promiseOne.then(function(){
    console.log("Promise consumed");
})

new Promise(function(resolve, reject){
    setTimeout(function(){
        console.log("Async task 2");
        resolve()
    }, 1000)

}).then(function(){
    console.log("Async 2 resolved");
})

const promiseThree = new Promise(function(resolve, reject){
    setTimeout(function(){
        resolve({username: "Chai", email: "chai@example.com"})
    }, 1000)
})

promiseThree.then(function(user){
    console.log(user);
})

const promiseFour = new Promise(function(resolve, reject){
    setTimeout(function(){
        let error = true
        if (!error) {
            resolve({username: "hitesh", password: "123"})
        } else {
            reject('ERROR: Something went wrong')
        }
    }, 1000)
})

promiseFour
    .then((user) => {
        console.log(user);
        return user.username
    })
    .then((username) => {
        console.log(username);
})
    .catch(function(error){
        console.log(error);
})
    .finally(() =>{
        console.log("The promise is either resolved or rejected")
    })


const promiseFive = new Promise(function(resolve, reject){
    setTimeout(function(){
        let error = true
        if (!error) {
            resolve({username: "javascript", password: "123"})
        } else {
            reject('ERROR: JS went wrong')
        }
    }, 1000)
});
//consuimg the promiseFive using async await
async function consumePromiseFive(){
    try {
        const response = await promiseFive
        console.log(response);
    } catch (error) {
        console.log(error);
    }
}

consumePromiseFive()

// async function getAllUsers(){
//     try {
//         const response = await fetch('https://jsonplaceholder.typicode.com/users')

//         const data = await response.json()
//         console.log(data);
//     } catch (error) {
//         console.log("E: ", error);
//     }
// }

//getAllUsers()

/*A fetch() promise only rejects when a network error is encountered 
(which is usually when there's a permissions issue or similar). 
A fetch() promise does not reject on HTTP errors (404, etc.). 
Instead, a then() handler must check the Response.ok and/or Response.status properties. 
The key point is that fetch() only rejects when a network error occurs, not for HTTP errors like 404. For HTTP errors, 
<you need to manually check the response status using Response.ok or Response.status*/

fetch('https://api.github.com/users/hiteshchoudhary')
.then((response) => {
    return response.json()
})
.then((data) => {
    console.log(data);
})
.catch((error) => console.log(error))

// promise.all
// yes this is also available, kuch reading aap b kro.